[2025-03-06T04:57:09.980+0000] {taskinstance.py:1165} INFO - Dependencies all met for <TaskInstance: covid19_etl.Extract scheduled__2025-03-06T04:54:00+00:00 [queued]>
[2025-03-06T04:57:10.005+0000] {taskinstance.py:1165} INFO - Dependencies all met for <TaskInstance: covid19_etl.Extract scheduled__2025-03-06T04:54:00+00:00 [queued]>
[2025-03-06T04:57:10.006+0000] {taskinstance.py:1362} INFO - 
--------------------------------------------------------------------------------
[2025-03-06T04:57:10.006+0000] {taskinstance.py:1363} INFO - Starting attempt 1 of 2
[2025-03-06T04:57:10.010+0000] {taskinstance.py:1364} INFO - 
--------------------------------------------------------------------------------
[2025-03-06T04:57:10.055+0000] {taskinstance.py:1383} INFO - Executing <Task(PythonOperator): Extract> on 2025-03-06 04:54:00+00:00
[2025-03-06T04:57:10.063+0000] {standard_task_runner.py:55} INFO - Started process 3345 to run task
[2025-03-06T04:57:10.070+0000] {standard_task_runner.py:82} INFO - Running: ['***', 'tasks', 'run', 'covid19_etl', 'Extract', 'scheduled__2025-03-06T04:54:00+00:00', '--job-id', '751', '--raw', '--subdir', 'DAGS_FOLDER/covid19-etl.py', '--cfg-path', '/tmp/tmpl3mfzavq']
[2025-03-06T04:57:10.073+0000] {standard_task_runner.py:83} INFO - Job 751: Subtask Extract
[2025-03-06T04:57:10.197+0000] {task_command.py:376} INFO - Running <TaskInstance: covid19_etl.Extract scheduled__2025-03-06T04:54:00+00:00 [running]> on host e5021ab2b3c4
[2025-03-06T04:57:10.331+0000] {taskinstance.py:1592} INFO - Exporting the following env vars:
AIRFLOW_CTX_DAG_OWNER=Sharaf
AIRFLOW_CTX_DAG_ID=covid19_etl
AIRFLOW_CTX_TASK_ID=Extract
AIRFLOW_CTX_EXECUTION_DATE=2025-03-06T04:54:00+00:00
AIRFLOW_CTX_TRY_NUMBER=1
AIRFLOW_CTX_DAG_RUN_ID=scheduled__2025-03-06T04:54:00+00:00
[2025-03-06T04:57:10.347+0000] {base.py:71} INFO - Using connection ID 'postgres_localhost' for task execution.
[2025-03-06T04:57:10.397+0000] {covid19-etl.py:46} INFO - Extracting data from source
[2025-03-06T04:57:10.899+0000] {covid19-etl.py:63} ERROR - Error extracting data for 01-02-2020: HTTP Error 404: Not Found
[2025-03-06T04:57:11.753+0000] {covid19-etl.py:53} INFO - Extracted data for 01-02-2021
[2025-03-06T04:57:12.885+0000] {covid19-etl.py:53} INFO - Extracted data for 01-02-2022
[2025-03-06T04:57:13.985+0000] {covid19-etl.py:53} INFO - Extracted data for 01-02-2023
[2025-03-06T04:57:14.233+0000] {python.py:177} INFO - Done. Returned value was: None
[2025-03-06T04:57:14.252+0000] {taskinstance.py:1406} INFO - Marking task as SUCCESS. dag_id=covid19_etl, task_id=Extract, execution_date=20250306T045400, start_date=20250306T045709, end_date=20250306T045714
[2025-03-06T04:57:14.308+0000] {local_task_job.py:164} INFO - Task exited with return code 0
[2025-03-06T04:57:14.379+0000] {local_task_job.py:273} INFO - 1 downstream tasks scheduled from follow-on schedule check
