[2025-03-06T05:00:10.272+0000] {taskinstance.py:1165} INFO - Dependencies all met for <TaskInstance: covid19_etl.Extract scheduled__2025-03-06T04:57:00+00:00 [queued]>
[2025-03-06T05:00:10.292+0000] {taskinstance.py:1165} INFO - Dependencies all met for <TaskInstance: covid19_etl.Extract scheduled__2025-03-06T04:57:00+00:00 [queued]>
[2025-03-06T05:00:10.292+0000] {taskinstance.py:1362} INFO - 
--------------------------------------------------------------------------------
[2025-03-06T05:00:10.293+0000] {taskinstance.py:1363} INFO - Starting attempt 1 of 2
[2025-03-06T05:00:10.293+0000] {taskinstance.py:1364} INFO - 
--------------------------------------------------------------------------------
[2025-03-06T05:00:10.324+0000] {taskinstance.py:1383} INFO - Executing <Task(PythonOperator): Extract> on 2025-03-06 04:57:00+00:00
[2025-03-06T05:00:10.336+0000] {standard_task_runner.py:55} INFO - Started process 3489 to run task
[2025-03-06T05:00:10.343+0000] {standard_task_runner.py:82} INFO - Running: ['***', 'tasks', 'run', 'covid19_etl', 'Extract', 'scheduled__2025-03-06T04:57:00+00:00', '--job-id', '757', '--raw', '--subdir', 'DAGS_FOLDER/covid19-etl.py', '--cfg-path', '/tmp/tmpbqxdxk60']
[2025-03-06T05:00:10.348+0000] {standard_task_runner.py:83} INFO - Job 757: Subtask Extract
[2025-03-06T05:00:10.554+0000] {task_command.py:376} INFO - Running <TaskInstance: covid19_etl.Extract scheduled__2025-03-06T04:57:00+00:00 [running]> on host e5021ab2b3c4
[2025-03-06T05:00:10.731+0000] {taskinstance.py:1592} INFO - Exporting the following env vars:
AIRFLOW_CTX_DAG_OWNER=Sharaf
AIRFLOW_CTX_DAG_ID=covid19_etl
AIRFLOW_CTX_TASK_ID=Extract
AIRFLOW_CTX_EXECUTION_DATE=2025-03-06T04:57:00+00:00
AIRFLOW_CTX_TRY_NUMBER=1
AIRFLOW_CTX_DAG_RUN_ID=scheduled__2025-03-06T04:57:00+00:00
[2025-03-06T05:00:10.751+0000] {base.py:71} INFO - Using connection ID 'postgres_localhost' for task execution.
[2025-03-06T05:00:10.800+0000] {covid19-etl.py:46} INFO - Extracting data from source
[2025-03-06T05:00:11.292+0000] {covid19-etl.py:63} ERROR - Error extracting data for 01-03-2020: HTTP Error 404: Not Found
[2025-03-06T05:00:12.152+0000] {covid19-etl.py:53} INFO - Extracted data for 01-03-2021
[2025-03-06T05:00:13.232+0000] {covid19-etl.py:53} INFO - Extracted data for 01-03-2022
[2025-03-06T05:00:14.256+0000] {covid19-etl.py:53} INFO - Extracted data for 01-03-2023
[2025-03-06T05:00:14.510+0000] {python.py:177} INFO - Done. Returned value was: None
[2025-03-06T05:00:14.527+0000] {taskinstance.py:1406} INFO - Marking task as SUCCESS. dag_id=covid19_etl, task_id=Extract, execution_date=20250306T045700, start_date=20250306T050010, end_date=20250306T050014
[2025-03-06T05:00:14.580+0000] {local_task_job.py:164} INFO - Task exited with return code 0
[2025-03-06T05:00:14.634+0000] {local_task_job.py:273} INFO - 1 downstream tasks scheduled from follow-on schedule check
